Workbook

Sheet Full Team Availability
B1: Monday | C1: Tuesday | D1: Wednesday | E1: Thursday | F1: Friday | G1: Saturday | H1: Sunday
A2: 0.20833333 | B2: =SUM('Marketing Team Availability'!B2,'Events Team Availability'!B2, N('Teresa Van'!B2), N('Chau Nguyen'!B2), N('Ninh Dang'!B2), N('Sodana Ung'!B2), N('Mimi Hang'!B2)) -> 1 | C2: =SUM('Marketing Team Availability'!C2,'Events Team Availability'!C2, N('Teresa Van'!C2), N('Chau Nguyen'!C2), N('Ninh Dang'!C2), N('Sodana Ung'!C2), N('Mimi Hang'!C2)) -> 1 | D2: =SUM('Marketing Team Availability'!D2,'Events Team Availability'!D2, N('Teresa Van'!D2), N('Chau Nguyen'!D2), N('Ninh Dang'!D2), N('Sodana Ung'!D2), N('Mimi Hang'!D2)) -> 1 | E2: =SUM('Marketing Team Availability'!E2,'Events Team Availability'!E2, N('Teresa Van'!E2), N('Chau Nguyen'!E2), N('Ninh Dang'!E2), N('Sodana Ung'!E2), N('Mimi Hang'!E2)) -> 2 | F2: =SUM('Marketing Team Availability'!F2,'Events Team Availability'!F2, N('Teresa Van'!F2), N('Chau Nguyen'!F2), N('Ninh Dang'!F2), N('Sodana Ung'!F2), N('Mimi Hang'!F2)) -> 1 | G2: =SUM('Marketing Team Availability'!G2,'Events Team Availability'!G2, N('Teresa Van'!G2), N('Chau Nguyen'!G2), N('Ninh Dang'!G2), N('Sodana Ung'!G2), N('Mimi Hang'!G2)) -> 5 | H2: =SUM('Marketing Team Availability'!H2,'Events Team Availability'!H2, N('Teresa Van'!H2), N('Chau Nguyen'!H2), N('Ninh Dang'!H2), N('Sodana Ung'!H2), N('Mimi Hang'!H2)) -> 4
A3: 0.25 | B3: =SUM('Marketing Team Availability'!B3,'Events Team Availability'!B3, N('Teresa Van'!B3), N('Chau Nguyen'!B3), N('Ninh Dang'!B3), N('Sodana Ung'!B3), N('Mimi Hang'!B3)) -> 0 | C3: =SUM('Marketing Team Availability'!C3,'Events Team Availability'!C3, N('Teresa Van'!C3), N('Chau Nguyen'!C3), N('Ninh Dang'!C3), N('Sodana Ung'!C3), N('Mimi Hang'!C3)) -> 0 | D3: =SUM('Marketing Team Availability'!D3,'Events Team Availability'!D3, N('Teresa Van'!D3), N('Chau Nguyen'!D3), N('Ninh Dang'!D3), N('Sodana Ung'!D3), N('Mimi Hang'!D3)) -> 0 | E3: =SUM('Marketing Team Availability'!E3,'Events Team Availability'!E3, N('Teresa Van'!E3), N('Chau Nguyen'!E3), N('Ninh Dang'!E3), N('Sodana Ung'!E3), N('Mimi Hang'!E3)) -> 1 | F3: =SUM('Marketing Team Availability'!F3,'Events Team Availability'!F3, N('Teresa Van'!F3), N('Chau Nguyen'!F3), N('Ninh Dang'!F3), N('Sodana Ung'!F3), N('Mimi Hang'!F3)) -> 0 | G3: =SUM('Marketing Team Availability'!G3,'Events Team Availability'!G3, N('Teresa Van'!G3), N('Chau Nguyen'!G3), N('Ninh Dang'!G3), N('Sodana Ung'!G3), N('Mimi Hang'!G3)) -> 4 | H3: =SUM('Marketing Team Availability'!H3,'Events Team Availability'!H3, N('Teresa Van'!H3), N('Chau Nguyen'!H3), N('Ninh Dang'!H3), N('Sodana Ung'!H3), N('Mimi Hang'!H3)) -> 3
A4: 0.29166667 | B4: =SUM('Marketing Team Availability'!B4,'Events Team Availability'!B4, N('Teresa Van'!B4), N('Chau Nguyen'!B4), N('Ninh Dang'!B4), N('Sodana Ung'!B4), N('Mimi Hang'!B4)) -> 0 | C4: =SUM('Marketing Team Availability'!C4,'Events Team Availability'!C4, N('Teresa Van'!C4), N('Chau Nguyen'!C4), N('Ninh Dang'!C4), N('Sodana Ung'!C4), N('Mimi Hang'!C4)) -> 0 | D4: =SUM('Marketing Team Availability'!D4,'Events Team Availability'!D4, N('Teresa Van'!D4), N('Chau Nguyen'!D4), N('Ninh Dang'!D4), N('Sodana Ung'!D4), N('Mimi Hang'!D4)) -> 0 | E4: =SUM('Marketing Team Availability'!E4,'Events Team Availability'!E4, N('Teresa Van'!E4), N('Chau Nguyen'!E4), N('Ninh Dang'!E4), N('Sodana Ung'!E4), N('Mimi Hang'!E4)) -> 1 | F4: =SUM('Marketing Team Availability'!F4,'Events Team Availability'!F4, N('Teresa Van'!F4), N('Chau Nguyen'!F4), N('Ninh Dang'!F4), N('Sodana Ung'!F4), N('Mimi Hang'!F4)) -> 0 | G4: =SUM('Marketing Team Availability'!G4,'Events Team Availability'!G4, N('Teresa Van'!G4), N('Chau Nguyen'!G4), N('Ninh Dang'!G4), N('Sodana Ung'!G4), N('Mimi Hang'!G4)) -> 4 | H4: =SUM('Marketing Team Availability'!H4,'Events Team Availability'!H4, N('Teresa Van'!H4), N('Chau Nguyen'!H4), N('Ninh Dang'!H4), N('Sodana Ung'!H4), N('Mimi Hang'!H4)) -> 3
A5: 0.33333333 | B5: =SUM('Marketing Team Availability'!B5,'Events Team Availability'!B5, N('Teresa Van'!B5), N('Chau Nguyen'!B5), N('Ninh Dang'!B5), N('Sodana Ung'!B5), N('Mimi Hang'!B5)) -> 1 | C5: =SUM('Marketing Team Availability'!C5,'Events Team Availability'!C5, N('Teresa Van'!C5), N('Chau Nguyen'!C5), N('Ninh Dang'!C5), N('Sodana Ung'!C5), N('Mimi Hang'!C5)) -> 0 | D5: =SUM('Marketing Team Availability'!D5,'Events Team Availability'!D5, N('Teresa Van'!D5), N('Chau Nguyen'!D5), N('Ninh Dang'!D5), N('Sodana Ung'!D5), N('Mimi Hang'!D5)) -> 1 | E5: =SUM('Marketing Team Availability'!E5,'Events Team Availability'!E5, N('Teresa Van'!E5), N('Chau Nguyen'!E5), N('Ninh Dang'!E5), N('Sodana Ung'!E5), N('Mimi Hang'!E5)) -> 1 | F5: =SUM('Marketing Team Availability'!F5,'Events Team Availability'!F5, N('Teresa Van'!F5), N('Chau Nguyen'!F5), N('Ninh Dang'!F5), N('Sodana Ung'!F5), N('Mimi Hang'!F5)) -> 1 | G5: =SUM('Marketing Team Availability'!G5,'Events Team Availability'!G5, N('Teresa Van'!G5), N('Chau Nguyen'!G5), N('Ninh Dang'!G5), N('Sodana Ung'!G5), N('Mimi Hang'!G5)) -> 4 | H5: =SUM('Marketing Team Availability'!H5,'Events Team Availability'!H5, N('Teresa Van'!H5), N('Chau Nguyen'!H5), N('Ninh Dang'!H5), N('Sodana Ung'!H5), N('Mimi Hang'!H5)) -> 3
A6: 0.375 | B6: =SUM('Marketing Team Availability'!B6,'Events Team Availability'!B6, N('Teresa Van'!B6), N('Chau Nguyen'!B6), N('Ninh Dang'!B6), N('Sodana Ung'!B6), N('Mimi Hang'!B6)) -> 1 | C6: =SUM('Marketing Team Availability'!C6,'Events Team Availability'!C6, N('Teresa Van'!C6), N('Chau Nguyen'!C6), N('Ninh Dang'!C6), N('Sodana Ung'!C6), N('Mimi Hang'!C6)) -> 0 | D6: =SUM('Marketing Team Availability'!D6,'Events Team Availability'!D6, N('Teresa Van'!D6), N('Chau Nguyen'!D6), N('Ninh Dang'!D6), N('Sodana Ung'!D6), N('Mimi Hang'!D6)) -> 1 | E6: =SUM('Marketing Team Availability'!E6,'Events Team Availability'!E6, N('Teresa Van'!E6), N('Chau Nguyen'!E6), N('Ninh Dang'!E6), N('Sodana Ung'!E6), N('Mimi Hang'!E6)) -> 2 | F6: =SUM('Marketing Team Availability'!F6,'Events Team Availability'!F6, N('Teresa Van'!F6), N('Chau Nguyen'!F6), N('Ninh Dang'!F6), N('Sodana Ung'!F6), N('Mimi Hang'!F6)) -> 1 | G6: =SUM('Marketing Team Availability'!G6,'Events Team Availability'!G6, N('Teresa Van'!G6), N('Chau Nguyen'!G6), N('Ninh Dang'!G6), N('Sodana Ung'!G6), N('Mimi Hang'!G6)) -> 4 | H6: =SUM('Marketing Team Availability'!H6,'Events Team Availability'!H6, N('Teresa Van'!H6), N('Chau Nguyen'!H6), N('Ninh Dang'!H6), N('Sodana Ung'!H6), N('Mimi Hang'!H6)) -> 3
A7: 0.41666667 | B7: =SUM('Marketing Team Availability'!B7,'Events Team Availability'!B7, N('Teresa Van'!B7), N('Chau Nguyen'!B7), N('Ninh Dang'!B7), N('Sodana Ung'!B7), N('Mimi Hang'!B7)) -> 1 | C7: =SUM('Marketing Team Availability'!C7,'Events Team Availability'!C7, N('Teresa Van'!C7), N('Chau Nguyen'!C7), N('Ninh Dang'!C7), N('Sodana Ung'!C7), N('Mimi Hang'!C7)) -> 1 | D7: =SUM('Marketing Team Availability'!D7,'Events Team Availability'!D7, N('Teresa Van'!D7), N('Chau Nguyen'!D7), N('Ninh Dang'!D7), N('Sodana Ung'!D7), N('Mimi Hang'!D7)) -> 1 | E7: =SUM('Marketing Team Availability'!E7,'Events Team Availability'!E7, N('Teresa Van'!E7), N('Chau Nguyen'!E7), N('Ninh Dang'!E7), N('Sodana Ung'!E7), N('Mimi Hang'!E7)) -> 2 | F7: =SUM('Marketing Team Availability'!F7,'Events Team Availability'!F7, N('Teresa Van'!F7), N('Chau Nguyen'!F7), N('Ninh Dang'!F7), N('Sodana Ung'!F7), N('Mimi Hang'!F7)) -> 2 | G7: =SUM('Marketing Team Availability'!G7,'Events Team Availability'!G7, N('Teresa Van'!G7), N('Chau Nguyen'!G7), N('Ninh Dang'!G7), N('Sodana Ung'!G7), N('Mimi Hang'!G7)) -> 5 | H7: =SUM('Marketing Team Availability'!H7,'Events Team Availability'!H7, N('Teresa Van'!H7), N('Chau Nguyen'!H7), N('Ninh Dang'!H7), N('Sodana Ung'!H7), N('Mimi Hang'!H7)) -> 4
A8: 0.45833333 | B8: =SUM('Marketing Team Availability'!B8,'Events Team Availability'!B8, N('Teresa Van'!B8), N('Chau Nguyen'!B8), N('Ninh Dang'!B8), N('Sodana Ung'!B8), N('Mimi Hang'!B8)) -> 1 | C8: =SUM('Marketing Team Availability'!C8,'Events Team Availability'!C8, N('Teresa Van'!C8), N('Chau Nguyen'!C8), N('Ninh Dang'!C8), N('Sodana Ung'!C8), N('Mimi Hang'!C8)) -> 2 | D8: =SUM('Marketing Team Availability'!D8,'Events Team Availability'!D8, N('Teresa Van'!D8), N('Chau Nguyen'!D8), N('Ninh Dang'!D8), N('Sodana Ung'!D8), N('Mimi Hang'!D8)) -> 1 | E8: =SUM('Marketing Team Availability'!E8,'Events Team Availability'!E8, N('Teresa Van'!E8), N('Chau Nguyen'!E8), N('Ninh Dang'!E8), N('Sodana Ung'!E8), N('Mimi Hang'!E8)) -> 2 | F8: =SUM('Marketing Team Availability'!F8,'Events Team Availability'!F8, N('Teresa Van'!F8), N('Chau Nguyen'!F8), N('Ninh Dang'!F8), N('Sodana Ung'!F8), N('Mimi Hang'!F8)) -> 3 | G8: =SUM('Marketing Team Availability'!G8,'Events Team Availability'!G8, N('Teresa Van'!G8), N('Chau Nguyen'!G8), N('Ninh Dang'!G8), N('Sodana Ung'!G8), N('Mimi Hang'!G8)) -> 5 | H8: =SUM('Marketing Team Availability'!H8,'Events Team Availability'!H8, N('Teresa Van'!H8), N('Chau Nguyen'!H8), N('Ninh Dang'!H8), N('Sodana Ung'!H8), N('Mimi Hang'!H8)) -> 4
A9: 0.5 | B9: =SUM('Marketing Team Availability'!B9,'Events Team Availability'!B9, N('Teresa Van'!B9), N('Chau Nguyen'!B9), N('Ninh Dang'!B9), N('Sodana Ung'!B9), N('Mimi Hang'!B9)) -> 4 | C9: =SUM('Marketing Team Availability'!C9,'Events Team Availability'!C9, N('Teresa Van'!C9), N('Chau Nguyen'!C9), N('Ninh Dang'!C9), N('Sodana Ung'!C9), N('Mimi Hang'!C9)) -> 4 | D9: =SUM('Marketing Team Availability'!D9,'Events Team Availability'!D9, N('Teresa Van'!D9), N('Chau Nguyen'!D9), N('Ninh Dang'!D9), N('Sodana Ung'!D9), N('Mimi Hang'!D9)) -> 3 | E9: =SUM('Marketing Team Availability'!E9,'Events Team Availability'!E9, N('Teresa Van'!E9), N('Chau Nguyen'!E9), N('Ninh Dang'!E9), N('Sodana Ung'!E9), N('Mimi Hang'!E9)) -> 2 | F9: =SUM('Marketing Team Availability'!F9,'Events Team Availability'!F9, N('Teresa Van'!F9), N('Chau Nguyen'!F9), N('Ninh Dang'!F9), N('Sodana Ung'!F9), N('Mimi Hang'!F9)) -> 3 | G9: =SUM('Marketing Team Availability'!G9,'Events Team Availability'!G9, N('Teresa Van'!G9), N('Chau Nguyen'!G9), N('Ninh Dang'!G9), N('Sodana Ung'!G9), N('Mimi Hang'!G9)) -> 5 | H9: =SUM('Marketing Team Availability'!H9,'Events Team Availability'!H9, N('Teresa Van'!H9), N('Chau Nguyen'!H9), N('Ninh Dang'!H9), N('Sodana Ung'!H9), N('Mimi Hang'!H9)) -> 5
A10: 0.54166667 | B10: =SUM('Marketing Team Availability'!B10,'Events Team Availability'!B10, N('Teresa Van'!B10), N('Chau Nguyen'!B10), N('Ninh Dang'!B10), N('Sodana Ung'!B10), N('Mimi Hang'!B10)) -> 5 | C10: =SUM('Marketing Team Availability'!C10,'Events Team Availability'!C10, N('Teresa Van'!C10), N('Chau Nguyen'!C10), N('Ninh Dang'!C10), N('Sodana Ung'!C10), N('Mimi Hang'!C10)) -> 5 | D10: =SUM('Marketing Team Availability'!D10,'Events Team Availability'!D10, N('Teresa Van'!D10), N('Chau Nguyen'!D10), N('Ninh Dang'!D10), N('Sodana Ung'!D10), N('Mimi Hang'!D10)) -> 4 | E10: =SUM('Marketing Team Availability'!E10,'Events Team Availability'!E10, N('Teresa Van'!E10), N('Chau Nguyen'!E10), N('Ninh Dang'!E10), N('Sodana Ung'!E10), N('Mimi Hang'!E10)) -> 4 | F10: =SUM('Marketing Team Availability'!F10,'Events Team Availability'!F10, N('Teresa Van'!F10), N('Chau Nguyen'!F10), N('Ninh Dang'!F10), N('Sodana Ung'!F10), N('Mimi Hang'!F10)) -> 3 | G10: =SUM('Marketing Team Availability'!G10,'Events Team Availability'!G10, N('Teresa Van'!G10), N('Chau Nguyen'!G10), N('Ninh Dang'!G10), N('Sodana Ung'!G10), N('Mimi Hang'!G10)) -> 5 | H10: =SUM('Marketing Team Availability'!H10,'Events Team Availability'!H10, N('Teresa Van'!H10), N('Chau Nguyen'!H10), N('Ninh Dang'!H10), N('Sodana Ung'!H10), N('Mimi Hang'!H10)) -> 5
A11: 0.58333333 | B11: =SUM('Marketing Team Availability'!B11,'Events Team Availability'!B11, N('Teresa Van'!B11), N('Chau Nguyen'!B11), N('Ninh Dang'!B11), N('Sodana Ung'!B11), N('Mimi Hang'!B11)) -> 6 | C11: =SUM('Marketing Team Availability'!C11,'Events Team Availability'!C11, N('Teresa Van'!C11), N('Chau Nguyen'!C11), N('Ninh Dang'!C11), N('Sodana Ung'!C11), N('Mimi Hang'!C11)) -> 5 | D11: =SUM('Marketing Team Availability'!D11,'Events Team Availability'!D11, N('Teresa Van'!D11), N('Chau Nguyen'!D11), N('Ninh Dang'!D11), N('Sodana Ung'!D11), N('Mimi Hang'!D11)) -> 4 | E11: =SUM('Marketing Team Availability'!E11,'Events Team Availability'!E11, N('Teresa Van'!E11), N('Chau Nguyen'!E11), N('Ninh Dang'!E11), N('Sodana Ung'!E11), N('Mimi Hang'!E11)) -> 4 | F11: =SUM('Marketing Team Availability'!F11,'Events Team Availability'!F11, N('Teresa Van'!F11), N('Chau Nguyen'!F11), N('Ninh Dang'!F11), N('Sodana Ung'!F11), N('Mimi Hang'!F11)) -> 3 | G11: =SUM('Marketing Team Availability'!G11,'Events Team Availability'!G11, N('Teresa Van'!G11), N('Chau Nguyen'!G11), N('Ninh Dang'!G11), N('Sodana Ung'!G11), N('Mimi Hang'!G11)) -> 4 | H11: =SUM('Marketing Team Availability'!H11,'Events Team Availability'!H11, N('Teresa Van'!H11), N('Chau Nguyen'!H11), N('Ninh Dang'!H11), N('Sodana Ung'!H11), N('Mimi Hang'!H11)) -> 4
A12: 0.625 | B12: =SUM('Marketing Team Availability'!B12,'Events Team Availability'!B12, N('Teresa Van'!B12), N('Chau Nguyen'!B12), N('Ninh Dang'!B12), N('Sodana Ung'!B12), N('Mimi Hang'!B12)) -> 7 | C12: =SUM('Marketing Team Availability'!C12,'Events Team Availability'!C12, N('Teresa Van'!C12), N('Chau Nguyen'!C12), N('Ninh Dang'!C12), N('Sodana Ung'!C12), N('Mimi Hang'!C12)) -> 5 | D12: =SUM('Marketing Team Availability'!D12,'Events Team Availability'!D12, N('Teresa Van'!D12), N('Chau Nguyen'!D12), N('Ninh Dang'!D12), N('Sodana Ung'!D12), N('Mimi Hang'!D12)) -> 6 | E12: =SUM('Marketing Team Availability'!E12,'Events Team Availability'!E12, N('Teresa Van'!E12), N('Chau Nguyen'!E12), N('Ninh Dang'!E12), N('Sodana Ung'!E12), N('Mimi Hang'!E12)) -> 5 | F12: =SUM('Marketing Team Availability'!F12,'Events Team Availability'!F12, N('Teresa Van'!F12), N('Chau Nguyen'!F12), N('Ninh Dang'!F12), N('Sodana Ung'!F12), N('Mimi Hang'!F12)) -> 3 | G12: =SUM('Marketing Team Availability'!G12,'Events Team Availability'!G12, N('Teresa Van'!G12), N('Chau Nguyen'!G12), N('Ninh Dang'!G12), N('Sodana Ung'!G12), N('Mimi Hang'!G12)) -> 4 | H12: =SUM('Marketing Team Availability'!H12,'Events Team Availability'!H12, N('Teresa Van'!H12), N('Chau Nguyen'!H12), N('Ninh Dang'!H12), N('Sodana Ung'!H12), N('Mimi Hang'!H12)) -> 5
A13: 0.66666667 | B13: =SUM('Marketing Team Availability'!B13,'Events Team Availability'!B13, N('Teresa Van'!B13), N('Chau Nguyen'!B13), N('Ninh Dang'!B13), N('Sodana Ung'!B13), N('Mimi Hang'!B13)) -> 7 | C13: =SUM('Marketing Team Availability'!C13,'Events Team Availability'!C13, N('Teresa Van'!C13), N('Chau Nguyen'!C13), N('Ninh Dang'!C13), N('Sodana Ung'!C13), N('Mimi Hang'!C13)) -> 5 | D13: =SUM('Marketing Team Availability'!D13,'Events Team Availability'!D13, N('Teresa Van'!D13), N('Chau Nguyen'!D13), N('Ninh Dang'!D13), N('Sodana Ung'!D13), N('Mimi Hang'!D13)) -> 6 | E13: =SUM('Marketing Team Availability'!E13,'Events Team Availability'!E13, N('Teresa Van'!E13), N('Chau Nguyen'!E13), N('Ninh Dang'!E13), N('Sodana Ung'!E13), N('Mimi Hang'!E13)) -> 4 | F13: =SUM('Marketing Team Availability'!F13,'Events Team Availability'!F13, N('Teresa Van'!F13), N('Chau Nguyen'!F13), N('Ninh Dang'!F13), N('Sodana Ung'!F13), N('Mimi Hang'!F13)) -> 3 | G13: =SUM('Marketing Team Availability'!G13,'Events Team Availability'!G13, N('Teresa Van'!G13), N('Chau Nguyen'!G13), N('Ninh Dang'!G13), N('Sodana Ung'!G13), N('Mimi Hang'!G13)) -> 4 | H13: =SUM('Marketing Team Availability'!H13,'Events Team Availability'!H13, N('Teresa Van'!H13), N('Chau Nguyen'!H13), N('Ninh Dang'!H13), N('Sodana Ung'!H13), N('Mimi Hang'!H13)) -> 5
... A21: 0 | B21: =SUM('Marketing Team Availability'!B21,'Events Team Availability'!B21, N('Teresa Van'!B21), N('Chau Nguyen'!B21), N('Ninh Dang'!B21), N('Sodana Ung'!B21), N('Mimi Hang'!B21)) -> 8 | C21: =SUM('Marketing Team Availability'!C21,'Events Team Availability'!C21, N('Teresa Van'!C21), N('Chau Nguyen'!C21), N('Ninh Dang'!C21), N('Sodana Ung'!C21), N('Mimi Hang'!C21)) -> 8 | D21: =SUM('Marketing Team Availability'!D21,'Events Team Availability'!D21, N('Teresa Van'!D21), N('Chau Nguyen'!D21), N('Ninh Dang'!D21), N('Sodana Ung'!D21), N('Mimi Hang'!D21)) -> 8 | E21: =SUM('Marketing Team Availability'!E21,'Events Team Availability'!E21, N('Teresa Van'!E21), N('Chau Nguyen'!E21), N('Ninh Dang'!E21), N('Sodana Ung'!E21), N('Mimi Hang'!E21)) -> 6 | F21: =SUM('Marketing Team Availability'!F21,'Events Team Availability'!F21, N('Teresa Van'!F21), N('Chau Nguyen'!F21), N('Ninh Dang'!F21), N('Sodana Ung'!F21), N('Mimi Hang'!F21)) -> 5 | G21: =SUM('Marketing Team Availability'!G21,'Events Team Availability'!G21, N('Teresa Van'!G21), N('Chau Nguyen'!G21), N('Ninh Dang'!G21), N('Sodana Ung'!G21), N('Mimi Hang'!G21)) -> 4 | H21: =SUM('Marketing Team Availability'!H21,'Events Team Availability'!H21, N('Teresa Van'!H21), N('Chau Nguyen'!H21), N('Ninh Dang'!H21), N('Sodana Ung'!H21), N('Mimi Hang'!H21)) -> 6

Sheet Marketing Team Availability
B1: Monday | C1: Tuesday | D1: Wednesday | E1: Thursday | F1: Friday | G1: Saturday | H1: Sunday
A2: 0.20833333 | B2: =SUM(N('Britney Phung'!B2), N('Michelle Bui'!B2), N('Hang Do'!B2), N('Alex Kieu'!B2), N('Bao Le'!B2), N('Presley Trinh'!B2), N('Wendy Truong'!B2), N('Ivy Vu'!B2)) -> 0 | C2: =SUM(N('Britney Phung'!C2), N('Michelle Bui'!C2), N('Hang Do'!C2), N('Alex Kieu'!C2), N('Bao Le'!C2), N('Presley Trinh'!C2), N('Wendy Truong'!C2), N('Ivy Vu'!C2)) -> 0 | D2: =SUM(N('Britney Phung'!D2), N('Michelle Bui'!D2), N('Hang Do'!D2), N('Alex Kieu'!D2), N('Bao Le'!D2), N('Presley Trinh'!D2), N('Wendy Truong'!D2), N('Ivy Vu'!D2)) -> 0 | E2: =SUM(N('Britney Phung'!E2), N('Michelle Bui'!E2), N('Hang Do'!E2), N('Alex Kieu'!E2), N('Bao Le'!E2), N('Presley Trinh'!E2), N('Wendy Truong'!E2), N('Ivy Vu'!E2)) -> 0 | F2: =SUM(N('Britney Phung'!F2), N('Michelle Bui'!F2), N('Hang Do'!F2), N('Alex Kieu'!F2), N('Bao Le'!F2), N('Presley Trinh'!F2), N('Wendy Truong'!F2), N('Ivy Vu'!F2)) -> 0 | G2: =SUM(N('Britney Phung'!G2), N('Michelle Bui'!G2), N('Hang Do'!G2), N('Alex Kieu'!G2), N('Bao Le'!G2), N('Presley Trinh'!G2), N('Wendy Truong'!G2), N('Ivy Vu'!G2)) -> 1 | H2: =SUM(N('Britney Phung'!H2), N('Michelle Bui'!H2), N('Hang Do'!H2), N('Alex Kieu'!H2), N('Bao Le'!H2), N('Presley Trinh'!H2), N('Wendy Truong'!H2), N('Ivy Vu'!H2)) -> 0
A3: 0.25 | B3: =SUM(N('Britney Phung'!B3), N('Michelle Bui'!B3), N('Hang Do'!B3), N('Alex Kieu'!B3), N('Bao Le'!B3), N('Presley Trinh'!B3), N('Wendy Truong'!B3), N('Ivy Vu'!B3)) -> 0 | C3: =SUM(N('Britney Phung'!C3), N('Michelle Bui'!C3), N('Hang Do'!C3), N('Alex Kieu'!C3), N('Bao Le'!C3), N('Presley Trinh'!C3), N('Wendy Truong'!C3), N('Ivy Vu'!C3)) -> 0 | D3: =SUM(N('Britney Phung'!D3), N('Michelle Bui'!D3), N('Hang Do'!D3), N('Alex Kieu'!D3), N('Bao Le'!D3), N('Presley Trinh'!D3), N('Wendy Truong'!D3), N('Ivy Vu'!D3)) -> 0 | E3: =SUM(N('Britney Phung'!E3), N('Michelle Bui'!E3), N('Hang Do'!E3), N('Alex Kieu'!E3), N('Bao Le'!E3), N('Presley Trinh'!E3), N('Wendy Truong'!E3), N('Ivy Vu'!E3)) -> 0 | F3: =SUM(N('Britney Phung'!F3), N('Michelle Bui'!F3), N('Hang Do'!F3), N('Alex Kieu'!F3), N('Bao Le'!F3), N('Presley Trinh'!F3), N('Wendy Truong'!F3), N('Ivy Vu'!F3)) -> 0 | G3: =SUM(N('Britney Phung'!G3), N('Michelle Bui'!G3), N('Hang Do'!G3), N('Alex Kieu'!G3), N('Bao Le'!G3), N('Presley Trinh'!G3), N('Wendy Truong'!G3), N('Ivy Vu'!G3)) -> 1 | H3: =SUM(N('Britney Phung'!H3), N('Michelle Bui'!H3), N('Hang Do'!H3), N('Alex Kieu'!H3), N('Bao Le'!H3), N('Presley Trinh'!H3), N('Wendy Truong'!H3), N('Ivy Vu'!H3)) -> 0
A4: 0.29166667 | B4: =SUM(N('Britney Phung'!B4), N('Michelle Bui'!B4), N('Hang Do'!B4), N('Alex Kieu'!B4), N('Bao Le'!B4), N('Presley Trinh'!B4), N('Wendy Truong'!B4), N('Ivy Vu'!B4)) -> 0 | C4: =SUM(N('Britney Phung'!C4), N('Michelle Bui'!C4), N('Hang Do'!C4), N('Alex Kieu'!C4), N('Bao Le'!C4), N('Presley Trinh'!C4), N('Wendy Truong'!C4), N('Ivy Vu'!C4)) -> 0 | D4: =SUM(N('Britney Phung'!D4), N('Michelle Bui'!D4), N('Hang Do'!D4), N('Alex Kieu'!D4), N('Bao Le'!D4), N('Presley Trinh'!D4), N('Wendy Truong'!D4), N('Ivy Vu'!D4)) -> 0 | E4: =SUM(N('Britney Phung'!E4), N('Michelle Bui'!E4), N('Hang Do'!E4), N('Alex Kieu'!E4), N('Bao Le'!E4), N('Presley Trinh'!E4), N('Wendy Truong'!E4), N('Ivy Vu'!E4)) -> 0 | F4: =SUM(N('Britney Phung'!F4), N('Michelle Bui'!F4), N('Hang Do'!F4), N('Alex Kieu'!F4), N('Bao Le'!F4), N('Presley Trinh'!F4), N('Wendy Truong'!F4), N('Ivy Vu'!F4)) -> 0 | G4: =SUM(N('Britney Phung'!G4), N('Michelle Bui'!G4), N('Hang Do'!G4), N('Alex Kieu'!G4), N('Bao Le'!G4), N('Presley Trinh'!G4), N('Wendy Truong'!G4), N('Ivy Vu'!G4)) -> 1 | H4: =SUM(N('Britney Phung'!H4), N('Michelle Bui'!H4), N('Hang Do'!H4), N('Alex Kieu'!H4), N('Bao Le'!H4), N('Presley Trinh'!H4), N('Wendy Truong'!H4), N('Ivy Vu'!H4)) -> 0
A5: 0.33333333 | B5: =SUM(N('Britney Phung'!B5), N('Michelle Bui'!B5), N('Hang Do'!B5), N('Alex Kieu'!B5), N('Bao Le'!B5), N('Presley Trinh'!B5), N('Wendy Truong'!B5), N('Ivy Vu'!B5)) -> 0 | C5: =SUM(N('Britney Phung'!C5), N('Michelle Bui'!C5), N('Hang Do'!C5), N('Alex Kieu'!C5), N('Bao Le'!C5), N('Presley Trinh'!C5), N('Wendy Truong'!C5), N('Ivy Vu'!C5)) -> 0 | D5: =SUM(N('Britney Phung'!D5), N('Michelle Bui'!D5), N('Hang Do'!D5), N('Alex Kieu'!D5), N('Bao Le'!D5), N('Presley Trinh'!D5), N('Wendy Truong'!D5), N('Ivy Vu'!D5)) -> 0 | E5: =SUM(N('Britney Phung'!E5), N('Michelle Bui'!E5), N('Hang Do'!E5), N('Alex Kieu'!E5), N('Bao Le'!E5), N('Presley Trinh'!E5), N('Wendy Truong'!E5), N('Ivy Vu'!E5)) -> 0 | F5: =SUM(N('Britney Phung'!F5), N('Michelle Bui'!F5), N('Hang Do'!F5), N('Alex Kieu'!F5), N('Bao Le'!F5), N('Presley Trinh'!F5), N('Wendy Truong'!F5), N('Ivy Vu'!F5)) -> 0 | G5: =SUM(N('Britney Phung'!G5), N('Michelle Bui'!G5), N('Hang Do'!G5), N('Alex Kieu'!G5), N('Bao Le'!G5), N('Presley Trinh'!G5), N('Wendy Truong'!G5), N('Ivy Vu'!G5)) -> 1 | H5: =SUM(N('Britney Phung'!H5), N('Michelle Bui'!H5), N('Hang Do'!H5), N('Alex Kieu'!H5), N('Bao Le'!H5), N('Presley Trinh'!H5), N('Wendy Truong'!H5), N('Ivy Vu'!H5)) -> 0
A6: 0.375 | B6: =SUM(N('Britney Phung'!B6), N('Michelle Bui'!B6), N('Hang Do'!B6), N('Alex Kieu'!B6), N('Bao Le'!B6), N('Presley Trinh'!B6), N('Wendy Truong'!B6), N('Ivy Vu'!B6)) -> 0 | C6: =SUM(N('Britney Phung'!C6), N('Michelle Bui'!C6), N('Hang Do'!C6), N('Alex Kieu'!C6), N('Bao Le'!C6), N('Presley Trinh'!C6), N('Wendy Truong'!C6), N('Ivy Vu'!C6)) -> 0 | D6: =SUM(N('Britney Phung'!D6), N('Michelle Bui'!D6), N('Hang Do'!D6), N('Alex Kieu'!D6), N('Bao Le'!D6), N('Presley Trinh'!D6), N('Wendy Truong'!D6), N('Ivy Vu'!D6)) -> 0 | E6: =SUM(N('Britney Phung'!E6), N('Michelle Bui'!E6), N('Hang Do'!E6), N('Alex Kieu'!E6), N('Bao Le'!E6), N('Presley Trinh'!E6), N('Wendy Truong'!E6), N('Ivy Vu'!E6)) -> 0 | F6: =SUM(N('Britney Phung'!F6), N('Michelle Bui'!F6), N('Hang Do'!F6), N('Alex Kieu'!F6), N('Bao Le'!F6), N('Presley Trinh'!F6), N('Wendy Truong'!F6), N('Ivy Vu'!F6)) -> 0 | G6: =SUM(N('Britney Phung'!G6), N('Michelle Bui'!G6), N('Hang Do'!G6), N('Alex Kieu'!G6), N('Bao Le'!G6), N('Presley Trinh'!G6), N('Wendy Truong'!G6), N('Ivy Vu'!G6)) -> 1 | H6: =SUM(N('Britney Phung'!H6), N('Michelle Bui'!H6), N('Hang Do'!H6), N('Alex Kieu'!H6), N('Bao Le'!H6), N('Presley Trinh'!H6), N('Wendy Truong'!H6), N('Ivy Vu'!H6)) -> 0
A7: 0.41666667 | B7: =SUM(N('Britney Phung'!B7), N('Michelle Bui'!B7), N('Hang Do'!B7), N('Alex Kieu'!B7), N('Bao Le'!B7), N('Presley Trinh'!B7), N('Wendy Truong'!B7), N('Ivy Vu'!B7)) -> 0 | C7: =SUM(N('Britney Phung'!C7), N('Michelle Bui'!C7), N('Hang Do'!C7), N('Alex Kieu'!C7), N('Bao Le'!C7), N('Presley Trinh'!C7), N('Wendy Truong'!C7), N('Ivy Vu'!C7)) -> 1 | D7: =SUM(N('Britney Phung'!D7), N('Michelle Bui'!D7), N('Hang Do'!D7), N('Alex Kieu'!D7), N('Bao Le'!D7), N('Presley Trinh'!D7), N('Wendy Truong'!D7), N('Ivy Vu'!D7)) -> 0 | E7: =SUM(N('Britney Phung'!E7), N('Michelle Bui'!E7), N('Hang Do'!E7), N('Alex Kieu'!E7), N('Bao Le'!E7), N('Presley Trinh'!E7), N('Wendy Truong'!E7), N('Ivy Vu'!E7)) -> 0 | F7: =SUM(N('Britney Phung'!F7), N('Michelle Bui'!F7), N('Hang Do'!F7), N('Alex Kieu'!F7), N('Bao Le'!F7), N('Presley Trinh'!F7), N('Wendy Truong'!F7), N('Ivy Vu'!F7)) -> 1 | G7: =SUM(N('Britney Phung'!G7), N('Michelle Bui'!G7), N('Hang Do'!G7), N('Alex Kieu'!G7), N('Bao Le'!G7), N('Presley Trinh'!G7), N('Wendy Truong'!G7), N('Ivy Vu'!G7)) -> 2 | H7: =SUM(N('Britney Phung'!H7), N('Michelle Bui'!H7), N('Hang Do'!H7), N('Alex Kieu'!H7), N('Bao Le'!H7), N('Presley Trinh'!H7), N('Wendy Truong'!H7), N('Ivy Vu'!H7)) -> 1
A8: 0.45833333 | B8: =SUM(N('Britney Phung'!B8), N('Michelle Bui'!B8), N('Hang Do'!B8), N('Alex Kieu'!B8), N('Bao Le'!B8), N('Presley Trinh'!B8), N('Wendy Truong'!B8), N('Ivy Vu'!B8)) -> 0 | C8: =SUM(N('Britney Phung'!C8), N('Michelle Bui'!C8), N('Hang Do'!C8), N('Alex Kieu'!C8), N('Bao Le'!C8), N('Presley Trinh'!C8), N('Wendy Truong'!C8), N('Ivy Vu'!C8)) -> 1 | D8: =SUM(N('Britney Phung'!D8), N('Michelle Bui'!D8), N('Hang Do'!D8), N('Alex Kieu'!D8), N('Bao Le'!D8), N('Presley Trinh'!D8), N('Wendy Truong'!D8), N('Ivy Vu'!D8)) -> 0 | E8: =SUM(N('Britney Phung'!E8), N('Michelle Bui'!E8), N('Hang Do'!E8), N('Alex Kieu'!E8), N('Bao Le'!E8), N('Presley Trinh'!E8), N('Wendy Truong'!E8), N('Ivy Vu'!E8)) -> 0 | F8: =SUM(N('Britney Phung'!F8), N('Michelle Bui'!F8), N('Hang Do'!F8), N('Alex Kieu'!F8), N('Bao Le'!F8), N('Presley Trinh'!F8), N('Wendy Truong'!F8), N('Ivy Vu'!F8)) -> 2 | G8: =SUM(N('Britney Phung'!G8), N('Michelle Bui'!G8), N('Hang Do'!G8), N('Alex Kieu'!G8), N('Bao Le'!G8), N('Presley Trinh'!G8), N('Wendy Truong'!G8), N('Ivy Vu'!G8)) -> 2 | H8: =SUM(N('Britney Phung'!H8), N('Michelle Bui'!H8), N('Hang Do'!H8), N('Alex Kieu'!H8), N('Bao Le'!H8), N('Presley Trinh'!H8), N('Wendy Truong'!H8), N('Ivy Vu'!H8)) -> 1
A9: 0.5 | B9: =SUM(N('Britney Phung'!B9), N('Michelle Bui'!B9), N('Hang Do'!B9), N('Alex Kieu'!B9), N('Bao Le'!B9), N('Presley Trinh'!B9), N('Wendy Truong'!B9), N('Ivy Vu'!B9)) -> 1 | C9: =SUM(N('Britney Phung'!C9), N('Michelle Bui'!C9), N('Hang Do'!C9), N('Alex Kieu'!C9), N('Bao Le'!C9), N('Presley Trinh'!C9), N('Wendy Truong'!C9), N('Ivy Vu'!C9)) -> 2 | D9: =SUM(N('Britney Phung'!D9), N('Michelle Bui'!D9), N('Hang Do'!D9), N('Alex Kieu'!D9), N('Bao Le'!D9), N('Presley Trinh'!D9), N('Wendy Truong'!D9), N('Ivy Vu'!D9)) -> 1 | E9: =SUM(N('Britney Phung'!E9), N('Michelle Bui'!E9), N('Hang Do'!E9), N('Alex Kieu'!E9), N('Bao Le'!E9), N('Presley Trinh'!E9), N('Wendy Truong'!E9), N('Ivy Vu'!E9)) -> 0 | F9: =SUM(N('Britney Phung'!F9), N('Michelle Bui'!F9), N('Hang Do'!F9), N('Alex Kieu'!F9), N('Bao Le'!F9), N('Presley Trinh'!F9), N('Wendy Truong'!F9), N('Ivy Vu'!F9)) -> 2 | G9: =SUM(N('Britney Phung'!G9), N('Michelle Bui'!G9), N('Hang Do'!G9), N('Alex Kieu'!G9), N('Bao Le'!G9), N('Presley Trinh'!G9), N('Wendy Truong'!G9), N('Ivy Vu'!G9)) -> 2 | H9: =SUM(N('Britney Phung'!H9), N('Michelle Bui'!H9), N('Hang Do'!H9), N('Alex Kieu'!H9), N('Bao Le'!H9), N('Presley Trinh'!H9), N('Wendy Truong'!H9), N('Ivy Vu'!H9)) -> 2
A10: 0.54166667 | B10: =SUM(N('Britney Phung'!B10), N('Michelle Bui'!B10), N('Hang Do'!B10), N('Alex Kieu'!B10), N('Bao Le'!B10), N('Presley Trinh'!B10), N('Wendy Truong'!B10), N('Ivy Vu'!B10)) -> 1 | C10: =SUM(N('Britney Phung'!C10), N('Michelle Bui'!C10), N('Hang Do'!C10), N('Alex Kieu'!C10), N('Bao Le'!C10), N('Presley Trinh'!C10), N('Wendy Truong'!C10), N('Ivy Vu'!C10)) -> 2 | D10: =SUM(N('Britney Phung'!D10), N('Michelle Bui'!D10), N('Hang Do'!D10), N('Alex Kieu'!D10), N('Bao Le'!D10), N('Presley Trinh'!D10), N('Wendy Truong'!D10), N('Ivy Vu'!D10)) -> 2 | E10: =SUM(N('Britney Phung'!E10), N('Michelle Bui'!E10), N('Hang Do'!E10), N('Alex Kieu'!E10), N('Bao Le'!E10), N('Presley Trinh'!E10), N('Wendy Truong'!E10), N('Ivy Vu'!E10)) -> 2 | F10: =SUM(N('Britney Phung'!F10), N('Michelle Bui'!F10), N('Hang Do'!F10), N('Alex Kieu'!F10), N('Bao Le'!F10), N('Presley Trinh'!F10), N('Wendy Truong'!F10), N('Ivy Vu'!F10)) -> 2 | G10: =SUM(N('Britney Phung'!G10), N('Michelle Bui'!G10), N('Hang Do'!G10), N('Alex Kieu'!G10), N('Bao Le'!G10), N('Presley Trinh'!G10), N('Wendy Truong'!G10), N('Ivy Vu'!G10)) -> 2 | H10: =SUM(N('Britney Phung'!H10), N('Michelle Bui'!H10), N('Hang Do'!H10), N('Alex Kieu'!H10), N('Bao Le'!H10), N('Presley Trinh'!H10), N('Wendy Truong'!H10), N('Ivy Vu'!H10)) -> 2
A11: 0.58333333 | B11: =SUM(N('Britney Phung'!B11), N('Michelle Bui'!B11), N('Hang Do'!B11), N('Alex Kieu'!B11), N('Bao Le'!B11), N('Presley Trinh'!B11), N('Wendy Truong'!B11), N('Ivy Vu'!B11)) -> 2 | C11: =SUM(N('Britney Phung'!C11), N('Michelle Bui'!C11), N('Hang Do'!C11), N('Alex Kieu'!C11), N('Bao Le'!C11), N('Presley Trinh'!C11), N('Wendy Truong'!C11), N('Ivy Vu'!C11)) -> 2 | D11: =SUM(N('Britney Phung'!D11), N('Michelle Bui'!D11), N('Hang Do'!D11), N('Alex Kieu'!D11), N('Bao Le'!D11), N('Presley Trinh'!D11), N('Wendy Truong'!D11), N('Ivy Vu'!D11)) -> 2 | E11: =SUM(N('Britney Phung'!E11), N('Michelle Bui'!E11), N('Hang Do'!E11), N('Alex Kieu'!E11), N('Bao Le'!E11), N('Presley Trinh'!E11), N('Wendy Truong'!E11), N('Ivy Vu'!E11)) -> 2 | F11: =SUM(N('Britney Phung'!F11), N('Michelle Bui'!F11), N('Hang Do'!F11), N('Alex Kieu'!F11), N('Bao Le'!F11), N('Presley Trinh'!F11), N('Wendy Truong'!F11), N('Ivy Vu'!F11)) -> 2 | G11: =SUM(N('Britney Phung'!G11), N('Michelle Bui'!G11), N('Hang Do'!G11), N('Alex Kieu'!G11), N('Bao Le'!G11), N('Presley Trinh'!G11), N('Wendy Truong'!G11), N('Ivy Vu'!G11)) -> 1 | H11: =SUM(N('Britney Phung'!H11), N('Michelle Bui'!H11), N('Hang Do'!H11), N('Alex Kieu'!H11), N('Bao Le'!H11), N('Presley Trinh'!H11), N('Wendy Truong'!H11), N('Ivy Vu'!H11)) -> 1
A12: 0.625 | B12: =SUM(N('Britney Phung'!B12), N('Michelle Bui'!B12), N('Hang Do'!B12), N('Alex Kieu'!B12), N('Bao Le'!B12), N('Presley Trinh'!B12), N('Wendy Truong'!B12), N('Ivy Vu'!B12)) -> 2 | C12: =SUM(N('Britney Phung'!C12), N('Michelle Bui'!C12), N('Hang Do'!C12), N('Alex Kieu'!C12), N('Bao Le'!C12), N('Presley Trinh'!C12), N('Wendy Truong'!C12), N('Ivy Vu'!C12)) -> 2 | D12: =SUM(N('Britney Phung'!D12), N('Michelle Bui'!D12), N('Hang Do'!D12), N('Alex Kieu'!D12), N('Bao Le'!D12), N('Presley Trinh'!D12), N('Wendy Truong'!D12), N('Ivy Vu'!D12)) -> 2 | E12: =SUM(N('Britney Phung'!E12), N('Michelle Bui'!E12), N('Hang Do'!E12), N('Alex Kieu'!E12), N('Bao Le'!E12), N('Presley Trinh'!E12), N('Wendy Truong'!E12), N('Ivy Vu'!E12)) -> 2 | F12: =SUM(N('Britney Phung'!F12), N('Michelle Bui'!F12), N('Hang Do'!F12), N('Alex Kieu'!F12), N('Bao Le'!F12), N('Presley Trinh'!F12), N('Wendy Truong'!F12), N('Ivy Vu'!F12)) -> 1 | G12: =SUM(N('Britney Phung'!G12), N('Michelle Bui'!G12), N('Hang Do'!G12), N('Alex Kieu'!G12), N('Bao Le'!G12), N('Presley Trinh'!G12), N('Wendy Truong'!G12), N('Ivy Vu'!G12)) -> 1 | H12: =SUM(N('Britney Phung'!H12), N('Michelle Bui'!H12), N('Hang Do'!H12), N('Alex Kieu'!H12), N('Bao Le'!H12), N('Presley Trinh'!H12), N('Wendy Truong'!H12), N('Ivy Vu'!H12)) -> 1
A13: 0.66666667 | B13: =SUM(N('Britney Phung'!B13), N('Michelle Bui'!B13), N('Hang Do'!B13), N('Alex Kieu'!B13), N('Bao Le'!B13), N('Presley Trinh'!B13), N('Wendy Truong'!B13), N('Ivy Vu'!B13)) -> 3 | C13: =SUM(N('Britney Phung'!C13), N('Michelle Bui'!C13), N('Hang Do'!C13), N('Alex Kieu'!C13), N('Bao Le'!C13), N('Presley Trinh'!C13), N('Wendy Truong'!C13), N('Ivy Vu'!C13)) -> 2 | D13: =SUM(N('Britney Phung'!D13), N('Michelle Bui'!D13), N('Hang Do'!D13), N('Alex Kieu'!D13), N('Bao Le'!D13), N('Presley Trinh'!D13), N('Wendy Truong'!D13), N('Ivy Vu'!D13)) -> 2 | E13: =SUM(N('Britney Phung'!E13), N('Michelle Bui'!E13), N('Hang Do'!E13), N('Alex Kieu'!E13), N('Bao Le'!E13), N('Presley Trinh'!E13), N('Wendy Truong'!E13), N('Ivy Vu'!E13)) -> 1 | F13: =SUM(N('Britney Phung'!F13), N('Michelle Bui'!F13), N('Hang Do'!F13), N('Alex Kieu'!F13), N('Bao Le'!F13), N('Presley Trinh'!F13), N('Wendy Truong'!F13), N('Ivy Vu'!F13)) -> 1 | G13: =SUM(N('Britney Phung'!G13), N('Michelle Bui'!G13), N('Hang Do'!G13), N('Alex Kieu'!G13), N('Bao Le'!G13), N('Presley Trinh'!G13), N('Wendy Truong'!G13), N('Ivy Vu'!G13)) -> 1 | H13: =SUM(N('Britney Phung'!H13), N('Michelle Bui'!H13), N('Hang Do'!H13), N('Alex Kieu'!H13), N('Bao Le'!H13), N('Presley Trinh'!H13), N('Wendy Truong'!H13), N('Ivy Vu'!H13)) -> 1
... A21: 0 | B21: =SUM(N('Britney Phung'!B21), N('Michelle Bui'!B21), N('Hang Do'!B21), N('Alex Kieu'!B21), N('Bao Le'!B21), N('Presley Trinh'!B21), N('Wendy Truong'!B21), N('Ivy Vu'!B21)) -> 3 | C21: =SUM(N('Britney Phung'!C21), N('Michelle Bui'!C21), N('Hang Do'!C21), N('Alex Kieu'!C21), N('Bao Le'!C21), N('Presley Trinh'!C21), N('Wendy Truong'!C21), N('Ivy Vu'!C21)) -> 3 | D21: =SUM(N('Britney Phung'!D21), N('Michelle Bui'!D21), N('Hang Do'!D21), N('Alex Kieu'!D21), N('Bao Le'!D21), N('Presley Trinh'!D21), N('Wendy Truong'!D21), N('Ivy Vu'!D21)) -> 3 | E21: =SUM(N('Britney Phung'!E21), N('Michelle Bui'!E21), N('Hang Do'!E21), N('Alex Kieu'!E21), N('Bao Le'!E21), N('Presley Trinh'!E21), N('Wendy Truong'!E21), N('Ivy Vu'!E21)) -> 3 | F21: =SUM(N('Britney Phung'!F21), N('Michelle Bui'!F21), N('Hang Do'!F21), N('Alex Kieu'!F21), N('Bao Le'!F21), N('Presley Trinh'!F21), N('Wendy Truong'!F21), N('Ivy Vu'!F21)) -> 1 | G21: =SUM(N('Britney Phung'!G21), N('Michelle Bui'!G21), N('Hang Do'!G21), N('Alex Kieu'!G21), N('Bao Le'!G21), N('Presley Trinh'!G21), N('Wendy Truong'!G21), N('Ivy Vu'!G21)) -> 1 | H21: =SUM(N('Britney Phung'!H21), N('Michelle Bui'!H21), N('Hang Do'!H21), N('Alex Kieu'!H21), N('Bao Le'!H21), N('Presley Trinh'!H21), N('Wendy Truong'!H21), N('Ivy Vu'!H21)) -> 3
B23: Includes: Britney P, Presley T, Wendy T, Bao L, Ivy V, Michelle B, Alex K, Hang Do

Sheet Events Team Availability
B1: Monday | C1: Tuesday | D1: Wednesday | E1: Thursday | F1: Friday | G1: Saturday | H1: Sunday
A2: 0.20833333 | B2: =SUM(N('Denis Thai'!B2), N('Stephen Nguyen'!B2), N('Jessica Hang'!B2), N('Calvin Truong'!B2), N('Carmen Choy'!B2), N('Kimmy Nguyen'!B2),N('Trang Pham'!B21)) -> 1 | C2: =SUM(N('Denis Thai'!C2), N('Stephen Nguyen'!C2), N('Jessica Hang'!C2), N('Calvin Truong'!C2), N('Carmen Choy'!C2), N('Kimmy Nguyen'!C2),N('Trang Pham'!C21)) -> 1 | D2: =SUM(N('Denis Thai'!D2), N('Stephen Nguyen'!D2), N('Jessica Hang'!D2), N('Calvin Truong'!D2), N('Carmen Choy'!D2), N('Kimmy Nguyen'!D2),N('Trang Pham'!D21)) -> 1 | E2: =SUM(N('Denis Thai'!E2), N('Stephen Nguyen'!E2), N('Jessica Hang'!E2), N('Calvin Truong'!E2), N('Carmen Choy'!E2), N('Kimmy Nguyen'!E2),N('Trang Pham'!E21)) -> 2 | F2: =SUM(N('Denis Thai'!F2), N('Stephen Nguyen'!F2), N('Jessica Hang'!F2), N('Calvin Truong'!F2), N('Carmen Choy'!F2), N('Kimmy Nguyen'!F2),N('Trang Pham'!F21)) -> 1 | G2: =SUM(N('Denis Thai'!G2), N('Stephen Nguyen'!G2), N('Jessica Hang'!G2), N('Calvin Truong'!G2), N('Carmen Choy'!G2), N('Kimmy Nguyen'!G2),N('Trang Pham'!G21)) -> 3 | H2: =SUM(N('Denis Thai'!H2), N('Stephen Nguyen'!H2), N('Jessica Hang'!H2), N('Calvin Truong'!H2), N('Carmen Choy'!H2), N('Kimmy Nguyen'!H2),N('Trang Pham'!H21)) -> 3
A3: 0.25 | B3: =SUM(N('Denis Thai'!B3), N('Stephen Nguyen'!B3), N('Jessica Hang'!B3), N('Calvin Truong'!B3), N('Carmen Choy'!B3), N('Kimmy Nguyen'!B3),N('Trang Pham'!B22)) -> 0 | C3: =SUM(N('Denis Thai'!C3), N('Stephen Nguyen'!C3), N('Jessica Hang'!C3), N('Calvin Truong'!C3), N('Carmen Choy'!C3), N('Kimmy Nguyen'!C3),N('Trang Pham'!C22)) -> 0 | D3: =SUM(N('Denis Thai'!D3), N('Stephen Nguyen'!D3), N('Jessica Hang'!D3), N('Calvin Truong'!D3), N('Carmen Choy'!D3), N('Kimmy Nguyen'!D3),N('Trang Pham'!D22)) -> 0 | E3: =SUM(N('Denis Thai'!E3), N('Stephen Nguyen'!E3), N('Jessica Hang'!E3), N('Calvin Truong'!E3), N('Carmen Choy'!E3), N('Kimmy Nguyen'!E3),N('Trang Pham'!E22)) -> 1 | F3: =SUM(N('Denis Thai'!F3), N('Stephen Nguyen'!F3), N('Jessica Hang'!F3), N('Calvin Truong'!F3), N('Carmen Choy'!F3), N('Kimmy Nguyen'!F3),N('Trang Pham'!F22)) -> 0 | G3: =SUM(N('Denis Thai'!G3), N('Stephen Nguyen'!G3), N('Jessica Hang'!G3), N('Calvin Truong'!G3), N('Carmen Choy'!G3), N('Kimmy Nguyen'!G3),N('Trang Pham'!G22)) -> 2 | H3: =SUM(N('Denis Thai'!H3), N('Stephen Nguyen'!H3), N('Jessica Hang'!H3), N('Calvin Truong'!H3), N('Carmen Choy'!H3), N('Kimmy Nguyen'!H3),N('Trang Pham'!H22)) -> 2
A4: 0.29166667 | B4: =SUM(N('Denis Thai'!B4), N('Stephen Nguyen'!B4), N('Jessica Hang'!B4), N('Calvin Truong'!B4), N('Carmen Choy'!B4), N('Kimmy Nguyen'!B4),N('Trang Pham'!B23)) -> 0 | C4: =SUM(N('Denis Thai'!C4), N('Stephen Nguyen'!C4), N('Jessica Hang'!C4), N('Calvin Truong'!C4), N('Carmen Choy'!C4), N('Kimmy Nguyen'!C4),N('Trang Pham'!C23)) -> 0 | D4: =SUM(N('Denis Thai'!D4), N('Stephen Nguyen'!D4), N('Jessica Hang'!D4), N('Calvin Truong'!D4), N('Carmen Choy'!D4), N('Kimmy Nguyen'!D4),N('Trang Pham'!D23)) -> 0 | E4: =SUM(N('Denis Thai'!E4), N('Stephen Nguyen'!E4), N('Jessica Hang'!E4), N('Calvin Truong'!E4), N('Carmen Choy'!E4), N('Kimmy Nguyen'!E4),N('Trang Pham'!E23)) -> 1 | F4: =SUM(N('Denis Thai'!F4), N('Stephen Nguyen'!F4), N('Jessica Hang'!F4), N('Calvin Truong'!F4), N('Carmen Choy'!F4), N('Kimmy Nguyen'!F4),N('Trang Pham'!F23)) -> 0 | G4: =SUM(N('Denis Thai'!G4), N('Stephen Nguyen'!G4), N('Jessica Hang'!G4), N('Calvin Truong'!G4), N('Carmen Choy'!G4), N('Kimmy Nguyen'!G4),N('Trang Pham'!G23)) -> 2 | H4: =SUM(N('Denis Thai'!H4), N('Stephen Nguyen'!H4), N('Jessica Hang'!H4), N('Calvin Truong'!H4), N('Carmen Choy'!H4), N('Kimmy Nguyen'!H4),N('Trang Pham'!H23)) -> 2
A5: 0.33333333 | B5: =SUM(N('Denis Thai'!B5), N('Stephen Nguyen'!B5), N('Jessica Hang'!B5), N('Calvin Truong'!B5), N('Carmen Choy'!B5), N('Kimmy Nguyen'!B5),N('Trang Pham'!B24)) -> 0 | C5: =SUM(N('Denis Thai'!C5), N('Stephen Nguyen'!C5), N('Jessica Hang'!C5), N('Calvin Truong'!C5), N('Carmen Choy'!C5), N('Kimmy Nguyen'!C5),N('Trang Pham'!C24)) -> 0 | D5: =SUM(N('Denis Thai'!D5), N('Stephen Nguyen'!D5), N('Jessica Hang'!D5), N('Calvin Truong'!D5), N('Carmen Choy'!D5), N('Kimmy Nguyen'!D5),N('Trang Pham'!D24)) -> 0 | E5: =SUM(N('Denis Thai'!E5), N('Stephen Nguyen'!E5), N('Jessica Hang'!E5), N('Calvin Truong'!E5), N('Carmen Choy'!E5), N('Kimmy Nguyen'!E5),N('Trang Pham'!E24)) -> 1 | F5: =SUM(N('Denis Thai'!F5), N('Stephen Nguyen'!F5), N('Jessica Hang'!F5), N('Calvin Truong'!F5), N('Carmen Choy'!F5), N('Kimmy Nguyen'!F5),N('Trang Pham'!F24)) -> 0 | G5: =SUM(N('Denis Thai'!G5), N('Stephen Nguyen'!G5), N('Jessica Hang'!G5), N('Calvin Truong'!G5), N('Carmen Choy'!G5), N('Kimmy Nguyen'!G5),N('Trang Pham'!G24)) -> 2 | H5: =SUM(N('Denis Thai'!H5), N('Stephen Nguyen'!H5), N('Jessica Hang'!H5), N('Calvin Truong'!H5), N('Carmen Choy'!H5), N('Kimmy Nguyen'!H5),N('Trang Pham'!H24)) -> 2
A6: 0.375 | B6: =SUM(N('Denis Thai'!B6), N('Stephen Nguyen'!B6), N('Jessica Hang'!B6), N('Calvin Truong'!B6), N('Carmen Choy'!B6), N('Kimmy Nguyen'!B6),N('Trang Pham'!B25)) -> 0 | C6: =SUM(N('Denis Thai'!C6), N('Stephen Nguyen'!C6), N('Jessica Hang'!C6), N('Calvin Truong'!C6), N('Carmen Choy'!C6), N('Kimmy Nguyen'!C6),N('Trang Pham'!C25)) -> 0 | D6: =SUM(N('Denis Thai'!D6), N('Stephen Nguyen'!D6), N('Jessica Hang'!D6), N('Calvin Truong'!D6), N('Carmen Choy'!D6), N('Kimmy Nguyen'!D6),N('Trang Pham'!D25)) -> 0 | E6: =SUM(N('Denis Thai'!E6), N('Stephen Nguyen'!E6), N('Jessica Hang'!E6), N('Calvin Truong'!E6), N('Carmen Choy'!E6), N('Kimmy Nguyen'!E6),N('Trang Pham'!E25)) -> 2 | F6: =SUM(N('Denis Thai'!F6), N('Stephen Nguyen'!F6), N('Jessica Hang'!F6), N('Calvin Truong'!F6), N('Carmen Choy'!F6), N('Kimmy Nguyen'!F6),N('Trang Pham'!F25)) -> 0 | G6: =SUM(N('Denis Thai'!G6), N('Stephen Nguyen'!G6), N('Jessica Hang'!G6), N('Calvin Truong'!G6), N('Carmen Choy'!G6), N('Kimmy Nguyen'!G6),N('Trang Pham'!G25)) -> 2 | H6: =SUM(N('Denis Thai'!H6), N('Stephen Nguyen'!H6), N('Jessica Hang'!H6), N('Calvin Truong'!H6), N('Carmen Choy'!H6), N('Kimmy Nguyen'!H6),N('Trang Pham'!H25)) -> 2
A7: 0.41666667 | B7: =SUM(N('Denis Thai'!B7), N('Stephen Nguyen'!B7), N('Jessica Hang'!B7), N('Calvin Truong'!B7), N('Carmen Choy'!B7), N('Kimmy Nguyen'!B7),N('Trang Pham'!B26)) -> 0 | C7: =SUM(N('Denis Thai'!C7), N('Stephen Nguyen'!C7), N('Jessica Hang'!C7), N('Calvin Truong'!C7), N('Carmen Choy'!C7), N('Kimmy Nguyen'!C7),N('Trang Pham'!C26)) -> 0 | D7: =SUM(N('Denis Thai'!D7), N('Stephen Nguyen'!D7), N('Jessica Hang'!D7), N('Calvin Truong'!D7), N('Carmen Choy'!D7), N('Kimmy Nguyen'!D7),N('Trang Pham'!D26)) -> 0 | E7: =SUM(N('Denis Thai'!E7), N('Stephen Nguyen'!E7), N('Jessica Hang'!E7), N('Calvin Truong'!E7), N('Carmen Choy'!E7), N('Kimmy Nguyen'!E7),N('Trang Pham'!E26)) -> 2 | F7: =SUM(N('Denis Thai'!F7), N('Stephen Nguyen'!F7), N('Jessica Hang'!F7), N('Calvin Truong'!F7), N('Carmen Choy'!F7), N('Kimmy Nguyen'!F7),N('Trang Pham'!F26)) -> 0 | G7: =SUM(N('Denis Thai'!G7), N('Stephen Nguyen'!G7), N('Jessica Hang'!G7), N('Calvin Truong'!G7), N('Carmen Choy'!G7), N('Kimmy Nguyen'!G7),N('Trang Pham'!G26)) -> 2 | H7: =SUM(N('Denis Thai'!H7), N('Stephen Nguyen'!H7), N('Jessica Hang'!H7), N('Calvin Truong'!H7), N('Carmen Choy'!H7), N('Kimmy Nguyen'!H7),N('Trang Pham'!H26)) -> 2
A8: 0.45833333 | B8: =SUM(N('Denis Thai'!B8), N('Stephen Nguyen'!B8), N('Jessica Hang'!B8), N('Calvin Truong'!B8), N('Carmen Choy'!B8), N('Kimmy Nguyen'!B8),N('Trang Pham'!B27)) -> 0 | C8: =SUM(N('Denis Thai'!C8), N('Stephen Nguyen'!C8), N('Jessica Hang'!C8), N('Calvin Truong'!C8), N('Carmen Choy'!C8), N('Kimmy Nguyen'!C8),N('Trang Pham'!C27)) -> 1 | D8: =SUM(N('Denis Thai'!D8), N('Stephen Nguyen'!D8), N('Jessica Hang'!D8), N('Calvin Truong'!D8), N('Carmen Choy'!D8), N('Kimmy Nguyen'!D8),N('Trang Pham'!D27)) -> 0 | E8: =SUM(N('Denis Thai'!E8), N('Stephen Nguyen'!E8), N('Jessica Hang'!E8), N('Calvin Truong'!E8), N('Carmen Choy'!E8), N('Kimmy Nguyen'!E8),N('Trang Pham'!E27)) -> 2 | F8: =SUM(N('Denis Thai'!F8), N('Stephen Nguyen'!F8), N('Jessica Hang'!F8), N('Calvin Truong'!F8), N('Carmen Choy'!F8), N('Kimmy Nguyen'!F8),N('Trang Pham'!F27)) -> 0 | G8: =SUM(N('Denis Thai'!G8), N('Stephen Nguyen'!G8), N('Jessica Hang'!G8), N('Calvin Truong'!G8), N('Carmen Choy'!G8), N('Kimmy Nguyen'!G8),N('Trang Pham'!G27)) -> 2 | H8: =SUM(N('Denis Thai'!H8), N('Stephen Nguyen'!H8), N('Jessica Hang'!H8), N('Calvin Truong'!H8), N('Carmen Choy'!H8), N('Kimmy Nguyen'!H8),N('Trang Pham'!H27)) -> 2
A9: 0.5 | B9: =SUM(N('Denis Thai'!B9), N('Stephen Nguyen'!B9), N('Jessica Hang'!B9), N('Calvin Truong'!B9), N('Carmen Choy'!B9), N('Kimmy Nguyen'!B9),N('Trang Pham'!B28)) -> 2 | C9: =SUM(N('Denis Thai'!C9), N('Stephen Nguyen'!C9), N('Jessica Hang'!C9), N('Calvin Truong'!C9), N('Carmen Choy'!C9), N('Kimmy Nguyen'!C9),N('Trang Pham'!C28)) -> 2 | D9: =SUM(N('Denis Thai'!D9), N('Stephen Nguyen'!D9), N('Jessica Hang'!D9), N('Calvin Truong'!D9), N('Carmen Choy'!D9), N('Kimmy Nguyen'!D9),N('Trang Pham'!D28)) -> 1 | E9: =SUM(N('Denis Thai'!E9), N('Stephen Nguyen'!E9), N('Jessica Hang'!E9), N('Calvin Truong'!E9), N('Carmen Choy'!E9), N('Kimmy Nguyen'!E9),N('Trang Pham'!E28)) -> 2 | F9: =SUM(N('Denis Thai'!F9), N('Stephen Nguyen'!F9), N('Jessica Hang'!F9), N('Calvin Truong'!F9), N('Carmen Choy'!F9), N('Kimmy Nguyen'!F9),N('Trang Pham'!F28)) -> 0 | G9: =SUM(N('Denis Thai'!G9), N('Stephen Nguyen'!G9), N('Jessica Hang'!G9), N('Calvin Truong'!G9), N('Carmen Choy'!G9), N('Kimmy Nguyen'!G9),N('Trang Pham'!G28)) -> 2 | H9: =SUM(N('Denis Thai'!H9), N('Stephen Nguyen'!H9), N('Jessica Hang'!H9), N('Calvin Truong'!H9), N('Carmen Choy'!H9), N('Kimmy Nguyen'!H9),N('Trang Pham'!H28)) -> 2
A10: 0.54166667 | B10: =SUM(N('Denis Thai'!B10), N('Stephen Nguyen'!B10), N('Jessica Hang'!B10), N('Calvin Truong'!B10), N('Carmen Choy'!B10), N('Kimmy Nguyen'!B10),N('Trang Pham'!B29)) -> 3 | C10: =SUM(N('Denis Thai'!C10), N('Stephen Nguyen'!C10), N('Jessica Hang'!C10), N('Calvin Truong'!C10), N('Carmen Choy'!C10), N('Kimmy Nguyen'!C10),N('Trang Pham'!C29)) -> 2 | D10: =SUM(N('Denis Thai'!D10), N('Stephen Nguyen'!D10), N('Jessica Hang'!D10), N('Calvin Truong'!D10), N('Carmen Choy'!D10), N('Kimmy Nguyen'!D10),N('Trang Pham'!D29)) -> 1 | E10: =SUM(N('Denis Thai'!E10), N('Stephen Nguyen'!E10), N('Jessica Hang'!E10), N('Calvin Truong'!E10), N('Carmen Choy'!E10), N('Kimmy Nguyen'!E10),N('Trang Pham'!E29)) -> 2 | F10: =SUM(N('Denis Thai'!F10), N('Stephen Nguyen'!F10), N('Jessica Hang'!F10), N('Calvin Truong'!F10), N('Carmen Choy'!F10), N('Kimmy Nguyen'!F10),N('Trang Pham'!F29)) -> 0 | G10: =SUM(N('Denis Thai'!G10), N('Stephen Nguyen'!G10), N('Jessica Hang'!G10), N('Calvin Truong'!G10), N('Carmen Choy'!G10), N('Kimmy Nguyen'!G10),N('Trang Pham'!G29)) -> 2 | H10: =SUM(N('Denis Thai'!H10), N('Stephen Nguyen'!H10), N('Jessica Hang'!H10), N('Calvin Truong'!H10), N('Carmen Choy'!H10), N('Kimmy Nguyen'!H10),N('Trang Pham'!H29)) -> 2
A11: 0.58333333 | B11: =SUM(N('Denis Thai'!B11), N('Stephen Nguyen'!B11), N('Jessica Hang'!B11), N('Calvin Truong'!B11), N('Carmen Choy'!B11), N('Kimmy Nguyen'!B11),N('Trang Pham'!B30)) -> 4 | C11: =SUM(N('Denis Thai'!C11), N('Stephen Nguyen'!C11), N('Jessica Hang'!C11), N('Calvin Truong'!C11), N('Carmen Choy'!C11), N('Kimmy Nguyen'!C11),N('Trang Pham'!C30)) -> 2 | D11: =SUM(N('Denis Thai'!D11), N('Stephen Nguyen'!D11), N('Jessica Hang'!D11), N('Calvin Truong'!D11), N('Carmen Choy'!D11), N('Kimmy Nguyen'!D11),N('Trang Pham'!D30)) -> 1 | E11: =SUM(N('Denis Thai'!E11), N('Stephen Nguyen'!E11), N('Jessica Hang'!E11), N('Calvin Truong'!E11), N('Carmen Choy'!E11), N('Kimmy Nguyen'!E11),N('Trang Pham'!E30)) -> 2 | F11: =SUM(N('Denis Thai'!F11), N('Stephen Nguyen'!F11), N('Jessica Hang'!F11), N('Calvin Truong'!F11), N('Carmen Choy'!F11), N('Kimmy Nguyen'!F11),N('Trang Pham'!F30)) -> 1 | G11: =SUM(N('Denis Thai'!G11), N('Stephen Nguyen'!G11), N('Jessica Hang'!G11), N('Calvin Truong'!G11), N('Carmen Choy'!G11), N('Kimmy Nguyen'!G11),N('Trang Pham'!G30)) -> 2 | H11: =SUM(N('Denis Thai'!H11), N('Stephen Nguyen'!H11), N('Jessica Hang'!H11), N('Calvin Truong'!H11), N('Carmen Choy'!H11), N('Kimmy Nguyen'!H11),N('Trang Pham'!H30)) -> 2
A12: 0.625 | B12: =SUM(N('Denis Thai'!B12), N('Stephen Nguyen'!B12), N('Jessica Hang'!B12), N('Calvin Truong'!B12), N('Carmen Choy'!B12), N('Kimmy Nguyen'!B12),N('Trang Pham'!B31)) -> 5 | C12: =SUM(N('Denis Thai'!C12), N('Stephen Nguyen'!C12), N('Jessica Hang'!C12), N('Calvin Truong'!C12), N('Carmen Choy'!C12), N('Kimmy Nguyen'!C12),N('Trang Pham'!C31)) -> 3 | D12: =SUM(N('Denis Thai'!D12), N('Stephen Nguyen'!D12), N('Jessica Hang'!D12), N('Calvin Truong'!D12), N('Carmen Choy'!D12), N('Kimmy Nguyen'!D12),N('Trang Pham'!D31)) -> 3 | E12: =SUM(N('Denis Thai'!E12), N('Stephen Nguyen'!E12), N('Jessica Hang'!E12), N('Calvin Truong'!E12), N('Carmen Choy'!E12), N('Kimmy Nguyen'!E12),N('Trang Pham'!E31)) -> 3 | F12: =SUM(N('Denis Thai'!F12), N('Stephen Nguyen'!F12), N('Jessica Hang'!F12), N('Calvin Truong'!F12), N('Carmen Choy'!F12), N('Kimmy Nguyen'!F12),N('Trang Pham'!F31)) -> 2 | G12: =SUM(N('Denis Thai'!G12), N('Stephen Nguyen'!G12), N('Jessica Hang'!G12), N('Calvin Truong'!G12), N('Carmen Choy'!G12), N('Kimmy Nguyen'!G12),N('Trang Pham'!G31)) -> 2 | H12: =SUM(N('Denis Thai'!H12), N('Stephen Nguyen'!H12), N('Jessica Hang'!H12), N('Calvin Truong'!H12), N('Carmen Choy'!H12), N('Kimmy Nguyen'!H12),N('Trang Pham'!H31)) -> 3
A13: 0.66666667 | B13: =SUM(N('Denis Thai'!B13), N('Stephen Nguyen'!B13), N('Jessica Hang'!B13), N('Calvin Truong'!B13), N('Carmen Choy'!B13), N('Kimmy Nguyen'!B13),N('Trang Pham'!B32)) -> 4 | C13: =SUM(N('Denis Thai'!C13), N('Stephen Nguyen'!C13), N('Jessica Hang'!C13), N('Calvin Truong'!C13), N('Carmen Choy'!C13), N('Kimmy Nguyen'!C13),N('Trang Pham'!C32)) -> 3 | D13: =SUM(N('Denis Thai'!D13), N('Stephen Nguyen'!D13), N('Jessica Hang'!D13), N('Calvin Truong'!D13), N('Carmen Choy'!D13), N('Kimmy Nguyen'!D13),N('Trang Pham'!D32)) -> 3 | E13: =SUM(N('Denis Thai'!E13), N('Stephen Nguyen'!E13), N('Jessica Hang'!E13), N('Calvin Truong'!E13), N('Carmen Choy'!E13), N('Kimmy Nguyen'!E13),N('Trang Pham'!E32)) -> 2 | F13: =SUM(N('Denis Thai'!F13), N('Stephen Nguyen'!F13), N('Jessica Hang'!F13), N('Calvin Truong'!F13), N('Carmen Choy'!F13), N('Kimmy Nguyen'!F13),N('Trang Pham'!F32)) -> 2 | G13: =SUM(N('Denis Thai'!G13), N('Stephen Nguyen'!G13), N('Jessica Hang'!G13), N('Calvin Truong'!G13), N('Carmen Choy'!G13), N('Kimmy Nguyen'!G13),N('Trang Pham'!G32)) -> 2 | H13: =SUM(N('Denis Thai'!H13), N('Stephen Nguyen'!H13), N('Jessica Hang'!H13), N('Calvin Truong'!H13), N('Carmen Choy'!H13), N('Kimmy Nguyen'!H13),N('Trang Pham'!H32)) -> 3
... A21: 0 | B21: =SUM(N('Denis Thai'!B21), N('Stephen Nguyen'!B21), N('Jessica Hang'!B21), N('Calvin Truong'!B21), N('Carmen Choy'!B21), N('Kimmy Nguyen'!B21),N('Trang Pham'!B40)) -> 3 | C21: =SUM(N('Denis Thai'!C21), N('Stephen Nguyen'!C21), N('Jessica Hang'!C21), N('Calvin Truong'!C21), N('Carmen Choy'!C21), N('Kimmy Nguyen'!C21),N('Trang Pham'!C40)) -> 3 | D21: =SUM(N('Denis Thai'!D21), N('Stephen Nguyen'!D21), N('Jessica Hang'!D21), N('Calvin Truong'!D21), N('Carmen Choy'!D21), N('Kimmy Nguyen'!D21),N('Trang Pham'!D40)) -> 3 | E21: =SUM(N('Denis Thai'!E21), N('Stephen Nguyen'!E21), N('Jessica Hang'!E21), N('Calvin Truong'!E21), N('Carmen Choy'!E21), N('Kimmy Nguyen'!E21),N('Trang Pham'!E40)) -> 1 | F21: =SUM(N('Denis Thai'!F21), N('Stephen Nguyen'!F21), N('Jessica Hang'!F21), N('Calvin Truong'!F21), N('Carmen Choy'!F21), N('Kimmy Nguyen'!F21),N('Trang Pham'!F40)) -> 2 | G21: =SUM(N('Denis Thai'!G21), N('Stephen Nguyen'!G21), N('Jessica Hang'!G21), N('Calvin Truong'!G21), N('Carmen Choy'!G21), N('Kimmy Nguyen'!G21),N('Trang Pham'!G40)) -> 2 | H21: =SUM(N('Denis Thai'!H21), N('Stephen Nguyen'!H21), N('Jessica Hang'!H21), N('Calvin Truong'!H21), N('Carmen Choy'!H21), N('Kimmy Nguyen'!H21),N('Trang Pham'!H40)) -> 2
B23: Includes: Denis T, Stephen N, Jessica H, Calvin T, Carmen C, Kimmy N

Sheet Britney Phung
B1: Monday | C1: Tuesday | D1: Wednesday | E1: Thursday | F1: Friday | G1: Saturday | H1: Sunday
A2: 0.20833333 | B2: FALSE | C2: FALSE | D2: FALSE | E2: FALSE | F2: FALSE | G2: FALSE | H2: FALSE
A3: 0.25 | B3: FALSE | C3: FALSE | D3: FALSE | E3: FALSE | F3: FALSE | G3: FALSE | H3: FALSE
A4: 0.29166667 | B4: FALSE | C4: FALSE | D4: FALSE | E4: FALSE | F4: FALSE | G4: FALSE | H4: FALSE
A5: 0.33333333 | B5: FALSE | C5: FALSE | D5: FALSE | E5: FALSE | F5: FALSE | G5: FALSE | H5: FALSE
A6: 0.375 | B6: FALSE | C6: FALSE | D6: FALSE | E6: FALSE | F6: FALSE | G6: FALSE | H6: FALSE
A7: 0.41666667 | B7: FALSE | C7: FALSE | D7: FALSE | E7: FALSE | F7: FALSE | G7: FALSE | H7: FALSE
A8: 0.45833333 | B8: FALSE | C8: FALSE | D8: FALSE | E8: FALSE | F8: FALSE | G8: FALSE | H8: FALSE
A9: 0.5 | B9: FALSE | C9: FALSE | D9: FALSE | E9: FALSE | F9: FALSE | G9: FALSE | H9: FALSE
A10: 0.54166667 | B10: FALSE | C10: FALSE | D10: FALSE | E10: FALSE | F10: FALSE | G10: FALSE | H10: FALSE
A11: 0.58333333 | B11: TRUE | C11: FALSE | D11: FALSE | E11: FALSE | F11: FALSE | G11: FALSE | H11: FALSE
A12: 0.625 | B12: TRUE | C12: FALSE | D12: FALSE | E12: FALSE | F12: FALSE | G12: FALSE | H12: FALSE
A13: 0.66666667 | B13: TRUE | C13: FALSE | D13: FALSE | E13: FALSE | F13: FALSE | G13: FALSE | H13: FALSE
... A21: 0 | B21: FALSE | C21: FALSE | D21: FALSE | E21: FALSE | F21: FALSE | G21: FALSE | H21: FALSE

Sheet Michelle Bui
B1: Monday | C1: Tuesday | D1: Wednesday | E1: Thursday | F1: Friday | G1: Saturday | H1: Sunday
A2: 0.20833333 | B2: FALSE | C2: FALSE | D2: FALSE | E2: FALSE | F2: FALSE | G2: FALSE | H2: FALSE
A3: 0.25 | B3: FALSE | C3: FALSE | D3: FALSE | E3: FALSE | F3: FALSE | G3: FALSE | H3: FALSE
A4: 0.29166667 | B4: FALSE | C4: FALSE | D4: FALSE | E4: FALSE | F4: FALSE | G4: FALSE | H4: FALSE
A5: 0.33333333 | B5: FALSE | C5: FALSE | D5: FALSE | E5: FALSE | F5: FALSE | G5: FALSE | H5: FALSE
A6: 0.375 | B6: FALSE | C6: FALSE | D6: FALSE | E6: FALSE | F6: FALSE | G6: FALSE | H6: FALSE
A7: 0.41666667 | B7: FALSE | C7: FALSE | D7: FALSE | E7: FALSE | F7: FALSE | G7: TRUE | H7: TRUE
A8: 0.45833333 | B8: FALSE | C8: FALSE | D8: FALSE | E8: FALSE | F8: FALSE | G8: TRUE | H8: TRUE
A9: 0.5 | B9: FALSE | C9: FALSE | D9: FALSE | E9: FALSE | F9: FALSE | G9: TRUE | H9: TRUE
A10: 0.54166667 | B10: FALSE | C10: FALSE | D10: FALSE | E10: FALSE | F10: FALSE | G10: TRUE | H10: TRUE
A11: 0.58333333 | B11: FALSE | C11: FALSE | D11: FALSE | E11: FALSE | F11: FALSE | G11: FALSE | H11: FALSE
A12: 0.625 | B12: FALSE | C12: FALSE | D12: FALSE | E12: FALSE | F12: FALSE | G12: FALSE | H12: FALSE
A13: 0.66666667 | B13: FALSE | C13: FALSE | D13: FALSE | E13: FALSE | F13: FALSE | G13: FALSE | H13: FALSE
... A21: 0 | B21: TRUE | C21: TRUE | D21: TRUE | E21: TRUE | F21: TRUE | G21: FALSE | H21: FALSE

Sheet Hang Do
B1: Monday | C1: Tuesday | D1: Wednesday | E1: Thursday | F1: Friday | G1: Saturday | H1: Sunday
A2: 0.20833333 | B2: FALSE | C2: FALSE | D2: FALSE | E2: FALSE | F2: FALSE | G2: FALSE | H2: FALSE
A3: 0.25 | B3: FALSE | C3: FALSE | D3: FALSE | E3: FALSE | F3: FALSE | G3: FALSE | H3: FALSE
A4: 0.29166667 | B4: FALSE | C4: FALSE | D4: FALSE | E4: FALSE | F4: FALSE | G4: FALSE | H4: FALSE
A5: 0.33333333 | B5: FALSE | C5: FALSE | D5: FALSE | E5: FALSE | F5: FALSE | G5: FALSE | H5: FALSE
A6: 0.375 | B6: FALSE | C6: FALSE | D6: FALSE | E6: FALSE | F6: FALSE | G6: FALSE | H6: FALSE
A7: 0.41666667 | B7: FALSE | C7: FALSE | D7: FALSE | E7: FALSE | F7: FALSE | G7: FALSE | H7: FALSE
A8: 0.45833333 | B8: FALSE | C8: FALSE | D8: FALSE | E8: FALSE | F8: TRUE | G8: FALSE | H8: FALSE
A9: 0.5 | B9: FALSE | C9: FALSE | D9: TRUE | E9: FALSE | F9: TRUE | G9: FALSE | H9: FALSE
A10: 0.54166667 | B10: FALSE | C10: TRUE | D10: TRUE | E10: FALSE | F10: TRUE | G10: FALSE | H10: FALSE
A11: 0.58333333 | B11: FALSE | C11: TRUE | D11: TRUE | E11: FALSE | F11: TRUE | G11: FALSE | H11: FALSE
A12: 0.625 | B12: FALSE | C12: TRUE | D12: TRUE | E12: FALSE | F12: FALSE | G12: FALSE | H12: FALSE
A13: 0.66666667 | B13: FALSE | C13: TRUE | D13: TRUE | E13: FALSE | F13: FALSE | G13: FALSE | H13: FALSE
... A21: 0 | B21: TRUE | C21: TRUE | D21: TRUE | E21: TRUE | F21: FALSE | G21: TRUE | H21: TRUE

Sheet Alex Kieu
B1: Monday | C1: Tuesday | D1: Wednesday | E1: Thursday | F1: Friday | G1: Saturday | H1: Sunday
A2: 0.20833333 | B2: FALSE | C2: FALSE | D2: FALSE | E2: FALSE | F2: FALSE | G2: FALSE | H2: FALSE
A3: 0.25 | B3: FALSE | C3: FALSE | D3: FALSE | E3: FALSE | F3: FALSE | G3: FALSE | H3: FALSE
A4: 0.29166667 | B4: FALSE | C4: FALSE | D4: FALSE | E4: FALSE | F4: FALSE | G4: FALSE | H4: FALSE
A5: 0.33333333 | B5: FALSE | C5: FALSE | D5: FALSE | E5: FALSE | F5: FALSE | G5: FALSE | H5: FALSE
A6: 0.375 | B6: FALSE | C6: FALSE | D6: FALSE | E6: FALSE | F6: FALSE | G6: FALSE | H6: FALSE
A7: 0.41666667 | B7: FALSE | C7: TRUE | D7: FALSE | E7: FALSE | F7: TRUE | G7: FALSE | H7: FALSE
A8: 0.45833333 | B8: FALSE | C8: TRUE | D8: FALSE | E8: FALSE | F8: TRUE | G8: FALSE | H8: FALSE
A9: 0.5 | B9: FALSE | C9: TRUE | D9: FALSE | E9: FALSE | F9: TRUE | G9: FALSE | H9: FALSE
A10: 0.54166667 | B10: FALSE | C10: FALSE | D10: FALSE | E10: FALSE | F10: FALSE | G10: FALSE | H10: FALSE
A11: 0.58333333 | B11: FALSE | C11: FALSE | D11: FALSE | E11: FALSE | F11: FALSE | G11: FALSE | H11: FALSE
A12: 0.625 | B12: FALSE | C12: FALSE | D12: FALSE | E12: FALSE | F12: FALSE | G12: FALSE | H12: FALSE
A13: 0.66666667 | B13: FALSE | C13: FALSE | D13: FALSE | E13: FALSE | F13: FALSE | G13: FALSE | H13: FALSE
... A21: 0 | B21: FALSE | C21: FALSE | D21: FALSE | E21: FALSE | F21: FALSE | G21: FALSE | H21: TRUE

Sheet Bao Le
B1: Monday | C1: Tuesday | D1: Wednesday | E1: Thursday | F1: Friday | G1: Saturday | H1: Sunday
A2: 0.20833333 | B2: FALSE | C2: FALSE | D2: FALSE | E2: FALSE | F2: FALSE | G2: FALSE | H2: FALSE
A3: 0.25 | B3: FALSE | C3: FALSE | D3: FALSE | E3: FALSE | F3: FALSE | G3: FALSE | H3: FALSE
A4: 0.29166667 | B4: FALSE | C4: FALSE | D4: FALSE | E4: FALSE | F4: FALSE | G4: FALSE | H4: FALSE
A5: 0.33333333 | B5: FALSE | C5: FALSE | D5: FALSE | E5: FALSE | F5: FALSE | G5: FALSE | H5: FALSE
A6: 0.375 | B6: FALSE | C6: FALSE | D6: FALSE | E6: FALSE | F6: FALSE | G6: FALSE | H6: FALSE
A7: 0.41666667 | B7: FALSE | C7: FALSE | D7: FALSE | E7: FALSE | F7: FALSE | G7: FALSE | H7: FALSE
A8: 0.45833333 | B8: FALSE | C8: FALSE | D8: FALSE | E8: FALSE | F8: FALSE | G8: FALSE | H8: FALSE
A9: 0.5 | B9: FALSE | C9: FALSE | D9: FALSE | E9: FALSE | F9: FALSE | G9: FALSE | H9: FALSE
A10: 0.54166667 | B10: FALSE | C10: FALSE | D10: FALSE | E10: FALSE | F10: TRUE | G10: FALSE | H10: FALSE
A11: 0.58333333 | B11: FALSE | C11: FALSE | D11: FALSE | E11: FALSE | F11: TRUE | G11: FALSE | H11: FALSE
A12: 0.625 | B12: FALSE | C12: FALSE | D12: FALSE | E12: FALSE | F12: TRUE | G12: FALSE | H12: FALSE
A13: 0.66666667 | B13: FALSE | C13: FALSE | D13: FALSE | E13: FALSE | F13: TRUE | G13: FALSE | H13: FALSE
... A21: 0 | B21: FALSE | C21: FALSE | D21: FALSE | E21: FALSE | F21: FALSE | G21: FALSE | H21: FALSE

Sheet Trang Pham
B1: Monday | C1: Tuesday | D1: Wednesday | E1: Thursday | F1: Friday | G1: Saturday | H1: Sunday
A2: 0.20833333 | B2: FALSE | C2: FALSE | D2: FALSE | E2: FALSE | F2: FALSE | G2: FALSE | H2: FALSE
A3: 0.25 | B3: FALSE | C3: FALSE | D3: FALSE | E3: FALSE | F3: FALSE | G3: FALSE | H3: FALSE
A4: 0.29166667 | B4: FALSE | C4: FALSE | D4: FALSE | E4: FALSE | F4: FALSE | G4: FALSE | H4: FALSE
A5: 0.33333333 | B5: FALSE | C5: FALSE | D5: FALSE | E5: FALSE | F5: FALSE | G5: FALSE | H5: FALSE
A6: 0.375 | B6: FALSE | C6: FALSE | D6: FALSE | E6: FALSE | F6: FALSE | G6: FALSE | H6: FALSE
A7: 0.41666667 | B7: FALSE | C7: FALSE | D7: FALSE | E7: FALSE | F7: TRUE | G7: FALSE | H7: TRUE
A8: 0.45833333 | B8: FALSE | C8: FALSE | D8: FALSE | E8: FALSE | F8: TRUE | G8: FALSE | H8: TRUE
A9: 0.5 | B9: FALSE | C9: FALSE | D9: FALSE | E9: FALSE | F9: TRUE | G9: FALSE | H9: TRUE
A10: 0.54166667 | B10: FALSE | C10: TRUE | D10: TRUE | E10: FALSE | F10: TRUE | G10: FALSE | H10: TRUE
A11: 0.58333333 | B11: FALSE | C11: TRUE | D11: TRUE | E11: FALSE | F11: TRUE | G11: FALSE | H11: TRUE
A12: 0.625 | B12: FALSE | C12: TRUE | D12: TRUE | E12: FALSE | F12: TRUE | G12: FALSE | H12: TRUE
A13: 0.66666667 | B13: FALSE | C13: TRUE | D13: TRUE | E13: FALSE | F13: TRUE | G13: FALSE | H13: TRUE
... A21: 0 | B21: TRUE | C21: TRUE | D21: TRUE | E21: TRUE | F21: TRUE | G21: TRUE | H21: TRUE

Sheet Presley Trinh
B1: Monday | C1: Tuesday | D1: Wednesday | E1: Thursday | F1: Friday | G1: Saturday | H1: Sunday
A2: 0.20833333 | B2: FALSE | C2: FALSE | D2: FALSE | E2: FALSE | F2: FALSE | G2: FALSE | H2: FALSE
A3: 0.25 | B3: FALSE | C3: FALSE | D3: FALSE | E3: FALSE | F3: FALSE | G3: FALSE | H3: FALSE
A4: 0.29166667 | B4: FALSE | C4: FALSE | D4: FALSE | E4: FALSE | F4: FALSE | G4: FALSE | H4: FALSE
A5: 0.33333333 | B5: FALSE | C5: FALSE | D5: FALSE | E5: FALSE | F5: FALSE | G5: FALSE | H5: FALSE
A6: 0.375 | B6: FALSE | C6: FALSE | D6: FALSE | E6: FALSE | F6: FALSE | G6: FALSE | H6: FALSE
A7: 0.41666667 | B7: FALSE | C7: FALSE | D7: FALSE | E7: FALSE | F7: FALSE | G7: FALSE | H7: FALSE
A8: 0.45833333 | B8: FALSE | C8: FALSE | D8: FALSE | E8: FALSE | F8: FALSE | G8: FALSE | H8: FALSE
A9: 0.5 | B9: FALSE | C9: FALSE | D9: FALSE | E9: FALSE | F9: FALSE | G9: FALSE | H9: FALSE
A10: 0.54166667 | B10: FALSE | C10: FALSE | D10: FALSE | E10: FALSE | F10: FALSE | G10: FALSE | H10: FALSE
A11: 0.58333333 | B11: FALSE | C11: FALSE | D11: FALSE | E11: FALSE | F11: FALSE | G11: FALSE | H11: FALSE
A12: 0.625 | B12: FALSE | C12: FALSE | D12: FALSE | E12: FALSE | F12: FALSE | G12: FALSE | H12: FALSE
A13: 0.66666667 | B13: FALSE | C13: FALSE | D13: FALSE | E13: FALSE | F13: FALSE | G13: FALSE | H13: FALSE
... A21: 0 | B21: FALSE | C21: FALSE | D21: FALSE | E21: FALSE | F21: FALSE | G21: FALSE | H21: FALSE

Sheet Wendy Truong
B1: Monday | C1: Tuesday | D1: Wednesday | E1: Thursday | F1: Friday | G1: Saturday | H1: Sunday
A2: 0.20833333 | B2: FALSE | C2: FALSE | D2: FALSE | E2: FALSE | F2: FALSE | G2: FALSE | H2: FALSE
A3: 0.25 | B3: FALSE | C3: FALSE | D3: FALSE | E3: FALSE | F3: FALSE | G3: FALSE | H3: FALSE
A4: 0.29166667 | B4: FALSE | C4: FALSE | D4: FALSE | E4: FALSE | F4: FALSE | G4: FALSE | H4: FALSE
A5: 0.33333333 | B5: FALSE | C5: FALSE | D5: FALSE | E5: FALSE | F5: FALSE | G5: FALSE | H5: FALSE
A6: 0.375 | B6: FALSE | C6: FALSE | D6: FALSE | E6: FALSE | F6: FALSE | G6: FALSE | H6: FALSE
A7: 0.41666667 | B7: FALSE | C7: FALSE | D7: FALSE | E7: FALSE | F7: FALSE | G7: FALSE | H7: FALSE
A8: 0.45833333 | B8: FALSE | C8: FALSE | D8: FALSE | E8: FALSE | F8: FALSE | G8: FALSE | H8: FALSE
